Loading LLAMA
Traceback (most recent call last):
  File "C:\Users\melvi\AppData\Local\Packages\PythonSoftwareFoundation.Python.3.12_qbz5n2kfra8p0\LocalCache\local-packages\Python312\site-packages\huggingface_hub\utils\_http.py", line 409, in hf_raise_for_status
    response.raise_for_status()
  File "C:\Users\melvi\AppData\Local\Packages\PythonSoftwareFoundation.Python.3.12_qbz5n2kfra8p0\LocalCache\local-packages\Python312\site-packages\requests\models.py", line 1024, in raise_for_status
    raise HTTPError(http_error_msg, response=self)
requests.exceptions.HTTPError: 401 Client Error: Unauthorized for url: https://huggingface.co/meta-llama/Llama-2-7b-hf/resolve/main/config.json

The above exception was the direct cause of the following exception:

Traceback (most recent call last):
  File "C:\Users\melvi\AppData\Local\Packages\PythonSoftwareFoundation.Python.3.12_qbz5n2kfra8p0\LocalCache\local-packages\Python312\site-packages\transformers\utils\hub.py", line 342, in cached_file
    resolved_file = hf_hub_download(
                    ^^^^^^^^^^^^^^^^
  File "C:\Users\melvi\AppData\Local\Packages\PythonSoftwareFoundation.Python.3.12_qbz5n2kfra8p0\LocalCache\local-packages\Python312\site-packages\huggingface_hub\utils\_validators.py", line 114, in _inner_fn
    return fn(*args, **kwargs)
           ^^^^^^^^^^^^^^^^^^^
  File "C:\Users\melvi\AppData\Local\Packages\PythonSoftwareFoundation.Python.3.12_qbz5n2kfra8p0\LocalCache\local-packages\Python312\site-packages\huggingface_hub\file_download.py", line 862, in hf_hub_download
    return _hf_hub_download_to_cache_dir(
           ^^^^^^^^^^^^^^^^^^^^^^^^^^^^^^
  File "C:\Users\melvi\AppData\Local\Packages\PythonSoftwareFoundation.Python.3.12_qbz5n2kfra8p0\LocalCache\local-packages\Python312\site-packages\huggingface_hub\file_download.py", line 969, in _hf_hub_download_to_cache_dir
    _raise_on_head_call_error(head_call_error, force_download, local_files_only)
  File "C:\Users\melvi\AppData\Local\Packages\PythonSoftwareFoundation.Python.3.12_qbz5n2kfra8p0\LocalCache\local-packages\Python312\site-packages\huggingface_hub\file_download.py", line 1486, in _raise_on_head_call_error
    raise head_call_error
  File "C:\Users\melvi\AppData\Local\Packages\PythonSoftwareFoundation.Python.3.12_qbz5n2kfra8p0\LocalCache\local-packages\Python312\site-packages\huggingface_hub\file_download.py", line 1376, in _get_metadata_or_catch_error
    metadata = get_hf_file_metadata(
               ^^^^^^^^^^^^^^^^^^^^^
  File "C:\Users\melvi\AppData\Local\Packages\PythonSoftwareFoundation.Python.3.12_qbz5n2kfra8p0\LocalCache\local-packages\Python312\site-packages\huggingface_hub\utils\_validators.py", line 114, in _inner_fn
    return fn(*args, **kwargs)
           ^^^^^^^^^^^^^^^^^^^
  File "C:\Users\melvi\AppData\Local\Packages\PythonSoftwareFoundation.Python.3.12_qbz5n2kfra8p0\LocalCache\local-packages\Python312\site-packages\huggingface_hub\file_download.py", line 1296, in get_hf_file_metadata
    r = _request_wrapper(
        ^^^^^^^^^^^^^^^^^
  File "C:\Users\melvi\AppData\Local\Packages\PythonSoftwareFoundation.Python.3.12_qbz5n2kfra8p0\LocalCache\local-packages\Python312\site-packages\huggingface_hub\file_download.py", line 280, in _request_wrapper
    response = _request_wrapper(
               ^^^^^^^^^^^^^^^^^
  File "C:\Users\melvi\AppData\Local\Packages\PythonSoftwareFoundation.Python.3.12_qbz5n2kfra8p0\LocalCache\local-packages\Python312\site-packages\huggingface_hub\file_download.py", line 304, in _request_wrapper
    hf_raise_for_status(response)
  File "C:\Users\melvi\AppData\Local\Packages\PythonSoftwareFoundation.Python.3.12_qbz5n2kfra8p0\LocalCache\local-packages\Python312\site-packages\huggingface_hub\utils\_http.py", line 426, in hf_raise_for_status
    raise _format(GatedRepoError, message, response) from e
huggingface_hub.errors.GatedRepoError: 401 Client Error. (Request ID: Root=1-680f8826-7b697c270c0693b05eff043d;b5fa102e-c09e-40da-ad82-cae7a614a46d)

Cannot access gated repo for url https://huggingface.co/meta-llama/Llama-2-7b-hf/resolve/main/config.json.
Access to model meta-llama/Llama-2-7b-hf is restricted. You must have access to it and be authenticated to access it. Please log in.

The above exception was the direct cause of the following exception:

Traceback (most recent call last):
  File "C:\Users\melvi\Documents\Melvin\ENSAI\Échange Prague\Cours\Large Language Models\GEM-Project-\train.py", line 140, in <module>
    main(args)
  File "C:\Users\melvi\Documents\Melvin\ENSAI\Échange Prague\Cours\Large Language Models\GEM-Project-\train.py", line 51, in main
    model = load_model[args.model_name](args=args)
            ^^^^^^^^^^^^^^^^^^^^^^^^^^^^^^^^^^^^^^
  File "C:\Users\melvi\Documents\Melvin\ENSAI\Échange Prague\Cours\Large Language Models\GEM-Project-\src\model\graph_llm.py", line 39, in __init__
    self.tokenizer = AutoTokenizer.from_pretrained(args.llm_model_path, use_fast=False, revision=kwargs["revision"])
                     ^^^^^^^^^^^^^^^^^^^^^^^^^^^^^^^^^^^^^^^^^^^^^^^^^^^^^^^^^^^^^^^^^^^^^^^^^^^^^^^^^^^^^^^^^^^^^^^
  File "C:\Users\melvi\AppData\Local\Packages\PythonSoftwareFoundation.Python.3.12_qbz5n2kfra8p0\LocalCache\local-packages\Python312\site-packages\transformers\models\auto\tokenization_auto.py", line 901, in from_pretrained
    config = AutoConfig.from_pretrained(
             ^^^^^^^^^^^^^^^^^^^^^^^^^^^
  File "C:\Users\melvi\AppData\Local\Packages\PythonSoftwareFoundation.Python.3.12_qbz5n2kfra8p0\LocalCache\local-packages\Python312\site-packages\transformers\models\auto\configuration_auto.py", line 1075, in from_pretrained
    config_dict, unused_kwargs = PretrainedConfig.get_config_dict(pretrained_model_name_or_path, **kwargs)
                                 ^^^^^^^^^^^^^^^^^^^^^^^^^^^^^^^^^^^^^^^^^^^^^^^^^^^^^^^^^^^^^^^^^^^^^^^^^
  File "C:\Users\melvi\AppData\Local\Packages\PythonSoftwareFoundation.Python.3.12_qbz5n2kfra8p0\LocalCache\local-packages\Python312\site-packages\transformers\configuration_utils.py", line 594, in get_config_dict
    config_dict, kwargs = cls._get_config_dict(pretrained_model_name_or_path, **kwargs)
                          ^^^^^^^^^^^^^^^^^^^^^^^^^^^^^^^^^^^^^^^^^^^^^^^^^^^^^^^^^^^^^
  File "C:\Users\melvi\AppData\Local\Packages\PythonSoftwareFoundation.Python.3.12_qbz5n2kfra8p0\LocalCache\local-packages\Python312\site-packages\transformers\configuration_utils.py", line 653, in _get_config_dict
    resolved_config_file = cached_file(
                           ^^^^^^^^^^^^
  File "C:\Users\melvi\AppData\Local\Packages\PythonSoftwareFoundation.Python.3.12_qbz5n2kfra8p0\LocalCache\local-packages\Python312\site-packages\transformers\utils\hub.py", line 360, in cached_file
    raise EnvironmentError(
OSError: You are trying to access a gated repo.
Make sure to have access to it at https://huggingface.co/meta-llama/Llama-2-7b-hf.
401 Client Error. (Request ID: Root=1-680f8826-7b697c270c0693b05eff043d;b5fa102e-c09e-40da-ad82-cae7a614a46d)

Cannot access gated repo for url https://huggingface.co/meta-llama/Llama-2-7b-hf/resolve/main/config.json.
Access to model meta-llama/Llama-2-7b-hf is restricted. You must have access to it and be authenticated to access it. Please log in.
